<mujoco model="go1_description">
  <compiler angle="radian"/>
  <!--<compiler angle="radian" assetdir="assets/robots/go1"/>-->
  <size njmax="500" nconmax="100"/>
  <option gravity='0 0 -9.806' iterations='50' solver='Newton' timestep='0.002'/>

  <default>
    <geom contype="1" conaffinity="1" friction="1.0 0.3 0.3" margin="0.001" group="0"/>
    <light castshadow="false" diffuse="1 1 1"/>
    <motor ctrlrange="-33.5 33.5" ctrllimited="true"/>
    <camera fovy="60"/>
    <joint damping="0.5" armature="0.01" frictionloss="0.2"/>
    <!-- Not sure if this is necessary-->
    <!--<position kp="20" forcerange="-33.5 33.5"/>-->
    <position kp="20" forcerange="-23.7 23.7"/>
  </default>

  <asset>
    <mesh name="trunk" file="go1/meshes/trunk.stl"/>
    <mesh name="hip" file="go1/meshes/hip.stl"/>
    <mesh name="thigh_mirror" file="go1/meshes/thigh_mirror.stl"/>
    <mesh name="calf" file="go1/meshes/calf.stl"/>
    <mesh name="thigh" file="go1/meshes/thigh.stl"/>
    <!--<texture type="skybox" builtin="gradient" rgb1="1.0 1.0 1.0" rgb2="1.0 1.0 1.0" width="512" height="512"/>-->
    <texture name="plane" type="2d" builtin="flat" rgb1="1 1 1" rgb2="1 1 1" width="512" height="512" mark="cross" markrgb="0 0 0"/>
    <material name="plane" reflectance="0.0" texture="plane" texrepeat="3 3" texuniform="true"/>
    <material name="go1" specular="0.3068755176666667" reflectance="1.0" shininess="0.025" rgba="0.3 0.3 0.3 0.9"/>
    <material name="go1-hip" specular="0.3068755176666667" shininess="0.025" rgba="0.2 0.2 0.2 0.9"/>
    <material name="go1-thigh" specular="0.9" reflectance="1.0" shininess="1.0" rgba="0.5 0.5 0.5 0.9"/>
  </asset>

  <visual>
    <rgba com="0.502 1.0 0 0.0" contactforce="0.98 0.4 0.4 0.7" contactpoint="1.0 1.0 0.6 0.4"/>
    <scale com="0.2" forcewidth="0.035" contactwidth="0.10" contactheight="0.04"/>
    <global offwidth="1280" offheight="768"/>
  </visual>

  <worldbody>
    <light directional="true" diffuse=".8 .8 .8" pos="0 0 10" dir="0 0 -10"/>
    <body name="trunk" pos="0 0 0.4">
      <camera name="tracking" mode="trackcom" pos="0 -1 1" xyaxes="1 0 0 0 1 1"/>
      <camera name="tracking-ground" mode="trackcom" pos="0 -1 -0.3" xyaxes="1 0 0 0 0 1"/>
      <camera name="tracking-2" mode="trackcom" pos="0 -1 0" xyaxes="1 0 0 0 0 1"/>
      <camera name="realsense" pos="0.27 0.0 0.015" xyaxes="0 -1 0 0 0 1" fovy="56.18593669466556"/>
      <camera name="ego-rgb" pos="0.27 0.0 0.015" xyaxes="0 -1 0 0 0 1" fovy="90"/>
      <camera name="ego-rgb-render" pos="0.27 0.0 0.015" xyaxes="0 -1 0 0 0 1" fovy="92.69673787219053"/>
<!--      <camera name="ego-rgb" pos="0.27 0.0 0.015" xyaxes="0 -1 0 0 0 1" fovy="42.61"/>-->
<!--      <camera name="ego-rgb-render" pos="0.27 0.0 0.015" xyaxes="0 -1 0 0 0 1" fovy="92.69673787219053"/>-->
      <camera name="realsense-rgb" pos="0.27 0.0 0.015" xyaxes="0 -1 0 0 0 1" fovy="42.61"/>
      <camera name="realsense-rgb-render" pos="0.27 0.0 0.015" xyaxes="0 -1 0 0 0 1" fovy="45.1729792"/>
      <camera name="heightmap" mode="trackcom" pos="0 0 25" xyaxes="0 -1 0 1 0 0" fovy="6"/>
      <inertial pos="0.0116053 0.00442221 0.000106692" quat="0.0111438 0.707126 -0.00935374 0.706938" mass="4.801"
                diaginertia="0.0447997 0.0366257 0.0162187"/>
      <joint type="free"/>
      <geom type="mesh" contype="0" conaffinity="0" group="1" rgba="0.913725 0.913725 0.847059 0.9" mesh="trunk"
            name="base"/>
        <body name="face" pos="0.27 0 0.015">
            <geom size="0.05 0.05 0.05" name="face" type="box" rgba="1 0 0 0"/>
        </body>
<!--        <body name="orin_box" pos="0.05 0 0.095">-->
<!--            <inertial mass="0" diaginertia="0 0 0" pos="0 0 0"/>-->
<!--            <geom size="0.055 0.055 0.035825" name="orin_box" type="box" rgba="0.1 0.1 0.1 0.9"/>-->
<!--        </body>-->
      <geom size="0.13 0.04675 0.057" type="box" rgba="0.913725 0.913725 0.847059 0.0"/>
      <site name="imu" pos="0 0 0"/>
      <body name="FR_hip" pos="0.1881 -0.04675 0">
        <inertial pos="-0.00406411 -0.0193463 4.50733e-06" quat="0.467526 0.531662 -0.466259 0.530431"
                  mass="0.679292" diaginertia="0.00131334 0.00122648 0.000728484"/>
        <joint name="FR_hip_joint" pos="0 0 0" axis="1 0 0" limited="true" range="-0.802851 0.802851"/>
        <geom quat="0 1 0 0" type="mesh" contype="0" conaffinity="0" group="1" mesh="hip" material="go1-hip" />
        <body name="FR_thigh" pos="0 -0.08 0">
          <inertial pos="-0.003468 0.018947 -0.032736" quat="0.999266 0.00067676 -0.0382978 0.000639813"
                    mass="0.898919" diaginertia="0.00542178 0.00514246 0.000998869"/>
          <joint name="FR_thigh_joint" pos="0 0 0" axis="0 1 0" limited="true" range="-1.0472 4.18879"/>
          <geom type="mesh" contype="0" conaffinity="0" group="1" mesh="thigh_mirror" material="go1-thigh"/>
          <geom size="0.1065 0.01225 0.017" pos="0 0 -0.1065" quat="0.707107 0 0.707107 0" type="box"
                rgba="0.913725 0.913725 0.847059 0"/>
          <body name="FR_calf" pos="0 0 -0.213">
            <inertial pos="0.00455603 0.0009473 -0.147239" quat="0.762045 0.00970173 0.0180098 0.647201"
                      mass="0.218015" diaginertia="0.00399678 0.00398122 3.99428e-05"/>
            <joint name="FR_calf_joint" pos="0 0 0" axis="0 1 0" limited="true" range="-2.69653 -0.916298"/>
            <geom type="mesh" contype="0" conaffinity="0" group="1" rgba="0 0 0 0.9" mesh="calf" material="go1" />
            <geom size="0.1065 0.008 0.008" pos="0 0 -0.1065" quat="0.707107 0 0.707107 0" type="box"
                  rgba="0 0 0 0"/>
            <geom size="0.01" pos="0 0 -0.213" contype="0" conaffinity="0" group="1" rgba="0 0 0 0.9"/>
            <geom size="0.02" pos="0 0 -0.213" rgba="0 0 0 0.9" name="FR"/>
          </body>
        </body>
      </body>
      <body name="FL_hip" pos="0.1881 0.04675 0">
        <inertial pos="-0.00406411 0.0193463 4.50733e-06" quat="0.531662 0.467526 -0.530431 0.466259"
                  mass="0.679292" diaginertia="0.00131334 0.00122648 0.000728484"/>
        <joint name="FL_hip_joint" pos="0 0 0" axis="1 0 0" limited="true" range="-0.802851 0.802851"/>
        <geom type="mesh" contype="0" conaffinity="0" group="1" mesh="hip" material="go1-hip" />
        <body name="FL_thigh" pos="0 0.08 0">
          <inertial pos="-0.003468 -0.018947 -0.032736" quat="0.999266 -0.00067676 -0.0382978 -0.000639813"
                    mass="0.898919" diaginertia="0.00542178 0.00514246 0.000998869"/>
          <joint name="FL_thigh_joint" pos="0 0 0" axis="0 1 0" limited="true" range="-1.0472 4.18879"/>
          <geom type="mesh" contype="0" conaffinity="0" group="1" mesh="thigh" material="go1-thigh" />
          <geom size="0.1065 0.01225 0.017" pos="0 0 -0.1065" quat="0.707107 0 0.707107 0" type="box"
                rgba="0.913725 0.913725 0.847059 0"/>
          <body name="FL_calf" pos="0 0 -0.213">
            <inertial pos="0.00455603 0.0009473 -0.147239" quat="0.762045 0.00970173 0.0180098 0.647201"
                      mass="0.218015" diaginertia="0.00399678 0.00398122 3.99428e-05"/>
            <joint name="FL_calf_joint" pos="0 0 0" axis="0 1 0" limited="true" range="-2.69653 -0.916298"/>
            <geom type="mesh" contype="0" conaffinity="0" group="1" rgba="0 0 0 0.9" mesh="calf" material="go1" />
            <geom size="0.1065 0.008 0.008" pos="0 0 -0.1065" quat="0.707107 0 0.707107 0" type="box"
                  rgba="0.913725 0.913725 0.847059 0"/>
            <geom size="0.01" pos="0 0 -0.213" contype="0" conaffinity="0" group="1" rgba="0 0 0 0.9"/>
            <geom size="0.02" pos="0 0 -0.213" rgba="0 0 0 0.9" name="FL"/>
          </body>
        </body>
      </body>
      <body name="RR_hip" pos="-0.1881 -0.04675 0">
        <inertial pos="0.00406411 -0.0193463 4.50733e-06" quat="0.530431 0.466259 -0.531662 0.467526"
                  mass="0.679292" diaginertia="0.00131334 0.00122648 0.000728484"/>
        <joint name="RR_hip_joint" pos="0 0 0" axis="1 0 0" limited="true" range="-0.802851 0.802851"/>
        <geom quat="0 0 0 -1" type="mesh" contype="0" conaffinity="0" group="1" mesh="hip" material="go1-hip" />
        <body name="RR_thigh" pos="0 -0.08 0">
          <inertial pos="-0.003468 0.018947 -0.032736" quat="0.999266 0.00067676 -0.0382978 0.000639813"
                    mass="0.898919" diaginertia="0.00542178 0.00514246 0.000998869"/>
          <joint name="RR_thigh_joint" pos="0 0 0" axis="0 1 0" limited="true" range="-1.0472 4.18879"/>
          <geom type="mesh" contype="0" conaffinity="0" group="1" mesh="thigh_mirror" material="go1-thigh"/>
          <geom size="0.1065 0.01225 0.017" pos="0 0 -0.1065" quat="0.707107 0 0.707107 0" type="box"
                rgba="0.913725 0.913725 0.847059 0"/>
          <body name="RR_calf" pos="0 0 -0.213">
            <inertial pos="0.00455603 0.0009473 -0.147239" quat="0.762045 0.00970173 0.0180098 0.647201"
                      mass="0.218015" diaginertia="0.00399678 0.00398122 3.99428e-05"/>
            <joint name="RR_calf_joint" pos="0 0 0" axis="0 1 0" limited="true" range="-2.69653 -0.916298"/>
            <geom type="mesh" contype="0" conaffinity="0" group="1" rgba="0 0 0 0.9" mesh="calf" material="go1" />
            <geom size="0.1065 0.008 0.008" pos="0 0 -0.1065" quat="0.707107 0 0.707107 0" type="box"
                  rgba="0 0 0 0"/>
            <geom size="0.01" pos="0 0 -0.213" contype="0" conaffinity="0" group="1" rgba="0 0 0 0.9"/>
            <geom size="0.02" pos="0 0 -0.213" rgba="0 0 0 0.9" name="RR"/>
          </body>
        </body>
      </body>
      <body name="RL_hip" pos="-0.1881 0.04675 0">
        <inertial pos="0.00406411 0.0193463 4.50733e-06" quat="0.466259 0.530431 -0.467526 0.531662"
                  mass="0.679292" diaginertia="0.00131334 0.00122648 0.000728484"/>
        <joint name="RL_hip_joint" pos="0 0 0" axis="1 0 0" limited="true" range="-0.802851 0.802851"/>
        <geom quat="0 0 1 0" type="mesh" contype="0" conaffinity="0" group="1" mesh="hip" material="go1-hip" />
        <body name="RL_thigh" pos="0 0.08 0">
          <inertial pos="-0.003468 -0.018947 -0.032736" quat="0.999266 -0.00067676 -0.0382978 -0.000639813"
                    mass="0.898919" diaginertia="0.00542178 0.00514246 0.000998869"/>
          <joint name="RL_thigh_joint" pos="0 0 0" axis="0 1 0" limited="true" range="-1.0472 4.18879"/>
          <geom type="mesh" contype="0" conaffinity="0" group="1" mesh="thigh" material="go1-thigh" />
          <geom size="0.1065 0.01225 0.017" pos="0 0 -0.1065" quat="0.707107 0 0.707107 0" type="box"
                rgba="0.913725 0.913725 0.847059 0"/>
          <body name="RL_calf" pos="0 0 -0.213">
            <inertial pos="0.00455603 0.0009473 -0.147239" quat="0.762045 0.00970173 0.0180098 0.647201"
                      mass="0.218015" diaginertia="0.00399678 0.00398122 3.99428e-05"/>
            <joint name="RL_calf_joint" pos="0 0 0" axis="0 1 0" limited="true" range="-2.69653 -0.916298"/>
            <geom type="mesh" contype="0" conaffinity="0" group="1" rgba="0 0 0 0.9" mesh="calf" material="go1" />
            <geom size="0.1065 0.008 0.008" pos="0 0 -0.1065" quat="0.707107 0 0.707107 0" type="box"
                  rgba="0 0 0 0"/>
            <geom size="0.01" pos="0 0 -0.213" contype="0" conaffinity="0" group="1" rgba="0 0 0 0.9"/>
            <geom size="0.02" pos="0 0 -0.213" rgba="0 0 0 0.9" name="RL"/>

          </body>
        </body>
      </body>
    </body>
<!--    <body name="flow-render-cam">-->
      <camera name="flow-render-cam" xyaxes="0 -1 0 0 0 1" fovy="92.69673787219053"/>
      <camera name="flow-cam" xyaxes="0 -1 0 0 0 1" fovy="90"/>
<!--    </body>-->
  </worldbody>
  <actuator>
    <position name="FR_hip" joint="FR_hip_joint"/>
    <position name="FR_thigh" joint="FR_thigh_joint"/>
    <position name="FR_calf" joint="FR_calf_joint"/>
    <position name="FL_hip" joint="FL_hip_joint"/>
    <position name="FL_thigh" joint="FL_thigh_joint"/>
    <position name="FL_calf" joint="FL_calf_joint"/>
    <position name="RR_hip" joint="RR_hip_joint"/>
    <position name="RR_thigh" joint="RR_thigh_joint"/>
    <position name="RR_calf" joint="RR_calf_joint"/>
    <position name="RL_hip" joint="RL_hip_joint"/>
    <position name="RL_thigh" joint="RL_thigh_joint"/>
    <position name="RL_calf" joint="RL_calf_joint"/>
    <!--        <motor name="FR_hip" gear="1" joint="FR_hip_joint"/>-->
    <!--        <motor name="FR_thigh" gear="1" joint="FR_thigh_joint"/>-->
    <!--        <motor name="FR_calf" gear="1" joint="FR_calf_joint"/>-->
    <!--        <motor name="FL_hip" gear="1" joint="FL_hip_joint"/>-->
    <!--        <motor name="FL_thigh" gear="1" joint="FL_thigh_joint"/>-->
    <!--        <motor name="FL_calf" gear="1" joint="FL_calf_joint"/>-->
    <!--        <motor name="RR_hip" gear="1" joint="RR_hip_joint"/>-->
    <!--        <motor name="RR_thigh" gear="1" joint="RR_thigh_joint"/>-->
    <!--        <motor name="RR_calf" gear="1" joint="RR_calf_joint"/>-->
    <!--        <motor name="RL_hip" gear="1" joint="RL_hip_joint"/>-->
    <!--        <motor name="RL_thigh" gear="1" joint="RL_thigh_joint"/>-->
    <!--        <motor name="RL_calf" gear="1" joint="RL_calf_joint"/>-->
  </actuator>

  <sensor>

    <jointpos name="FR_hip_pos" joint="FR_hip_joint"/>
    <jointpos name="FR_thigh_pos" joint="FR_thigh_joint"/>
    <jointpos name="FR_calf_pos" joint="FR_calf_joint"/>
    <jointpos name="FL_hip_pos" joint="FL_hip_joint"/>
    <jointpos name="FL_thigh_pos" joint="FL_thigh_joint"/>
    <jointpos name="FL_calf_pos" joint="FL_calf_joint"/>
    <jointpos name="RR_hip_pos" joint="RR_hip_joint"/>
    <jointpos name="RR_thigh_pos" joint="RR_thigh_joint"/>
    <jointpos name="RR_calf_pos" joint="RR_calf_joint"/>
    <jointpos name="RL_hip_pos" joint="RL_hip_joint"/>
    <jointpos name="RL_thigh_pos" joint="RL_thigh_joint"/>
    <jointpos name="RL_calf_pos" joint="RL_calf_joint"/>

    <jointvel name="FR_hip_vel" joint="FR_hip_joint"/>
    <jointvel name="FR_thigh_vel" joint="FR_thigh_joint"/>
    <jointvel name="FR_calf_vel" joint="FR_calf_joint"/>
    <jointvel name="FL_hip_vel" joint="FL_hip_joint"/>
    <jointvel name="FL_thigh_vel" joint="FL_thigh_joint"/>
    <jointvel name="FL_calf_vel" joint="FL_calf_joint"/>
    <jointvel name="RR_hip_vel" joint="RR_hip_joint"/>
    <jointvel name="RR_thigh_vel" joint="RR_thigh_joint"/>
    <jointvel name="RR_calf_vel" joint="RR_calf_joint"/>
    <jointvel name="RL_hip_vel" joint="RL_hip_joint"/>
    <jointvel name="RL_thigh_vel" joint="RL_thigh_joint"/>
    <jointvel name="RL_calf_vel" joint="RL_calf_joint"/>

    <accelerometer name="Body_Acc" site="imu"/>

    <gyro name="Body_Gyro" site="imu"/>

  </sensor>
</mujoco>
